Je komt met weer dezelfde trubleshoot dingen lees onderstaande caracter voor caracter en los in de kode alle problwemen op die je tegen komt beperk je niet tot kleine dingen wees extgreem. zorg dat je alles uit de kast haalt en weet wat eerder wel en niet gewerkt heeft. als je dat allemaal hebt gedaan loop je de kode nog 3 keer door op problemen en dan nog een keer als master test. 
 ● radiologger.service - Radiologger Web Application                             
      Loaded: loaded (/etc/systemd/system/radiologger.service; enabled; preset: >
      Active: active (running) since Sun 2025-03-30 18:23:11 UTC; 2s ago         
    Main PID: 33565 (gunicorn)                                                   
       Tasks: 4 (limit: 1113)                                                    
      Memory: 148.6M (peak: 148.8M)                                              
         CPU: 2.240s                                                             
      CGroup: /system.slice/radiologger.service                                  
              ├─33565 /opt/radiologger/venv/bin/python3 /opt/radiologger/venv/bi>
              ├─33566 /opt/radiologger/venv/bin/python3 /opt/radiologger/venv/bi>
              ├─33567 /opt/radiologger/venv/bin/python3 /opt/radiologger/venv/bi>
              └─33568 /opt/radiologger/venv/bin/python3 /opt/radiologger/venv/bi>
                                                                                 
 Mar 30 18:23:06 vpn systemd[1]: radiologger.service: Failed with result 'exit-c>
 Mar 30 18:23:06 vpn systemd[1]: radiologger.service: Consumed 2.952s CPU time.  
 Mar 30 18:23:11 vpn systemd[1]: radiologger.service: Scheduled restart job, res>
 Mar 30 18:23:11 vpn systemd[1]: Started radiologger.service - Radiologger Web A>
 Mar 30 18:23:11 vpn gunicorn[33566]: INFO:app:App configuratie geladen. Databas>
 Mar 30 18:23:12 vpn gunicorn[33567]: INFO:app:App configuratie geladen. Databas>
 Mar 30 18:23:12 vpn gunicorn[33568]: INFO:app:App configuratie geladen. Databas>
 Mar 30 18:23:13 vpn gunicorn[33566]: INFO:app:App configuratie geladen. Databas>
 Mar 30 18:23:13 vpn gunicorn[33567]: INFO:app:App configuratie geladen. Databas>
 Mar 30 18:23:13 vpn gunicorn[33568]: INFO:app:App configuratie geladen. Databas>
 sudo journalctl -u radiologger -n 50 lijkt dezelfde info te geven
sudo lsof -i :5000 geeft geen output
 root@vpn:~# /opt/radiologger/venv/bin/gunicorn --version                        
 gunicorn (version 23.0.0)                                                       
 
 py", line 47, in load_wsgiapp                                                   
     return util.import_app(self.app_uri)                                        
            ^^^^^^^^^^^^^^^^^^^^^^^^^^^^^                                        
   File "/opt/radiologger/venv/lib/python3.12/site-packages/gunicorn/util.py", li
 ne 370, in import_app                                                           
     mod = importlib.import_module(module)                                       
           ^^^^^^^^^^^^^^^^^^^^^^^^^^^^^^^                                       
   File "/usr/lib/python3.12/importlib/__init__.py", line 90, in import_module   
     return _bootstrap._gcd_import(name[level:], package, level)                 
            ^^^^^^^^^^^^^^^^^^^^^^^^^^^^^^^^^^^^^^^^^^^^^^^^^^^^                 
   File "<frozen importlib._bootstrap>", line 1387, in _gcd_import               
   File "<frozen importlib._bootstrap>", line 1360, in _find_and_load            
   File "<frozen importlib._bootstrap>", line 1331, in _find_and_load_unlocked   
   File "<frozen importlib._bootstrap>", line 935, in _load_unlocked             
   File "<frozen importlib._bootstrap_external>", line 995, in exec_module       
   File "<frozen importlib._bootstrap>", line 488, in _call_with_frames_removed  
   File "/opt/radiologger/main.py", line 33, in <module>                         
     from app import app as flask_app                                            
   File "/opt/radiologger/app.py", line 82, in <module>                          
     from auth import auth_bp                                                    
   File "/opt/radiologger/auth.py", line 6, in <module>                          
     from forms import LoginForm, UserForm                                       
 ModuleNotFoundError: No module named 'forms'                                    
 
de eenvoudige app.pi hadden we ooit weleens gemaakt ik zie niet in waarom dat nog zin zou hebben waarin je de kode nogmaals tegen de foutmeldingen aan houdt en beredeneerd of dit zo alllemaal is opgelost.
